Workbook
Name Escolha_Única__Vertical: 'Opções - Tipo de Resposta'!$A$3:$A$6

Sheet Status_Legenda
A1: Status | B1: Descrição
A2: Em elaboração | B2: A pergunta está em elaboração, não modifique o enunciado.
A3: Disponível para revisão | B3: A pergunta está disponível para revisão, não foram feitas ressalvas pela Oppen.
A4: Disponível para revisão com ressalvas | B4: A pergunta está disponível para revisão com ressalvas, foram feitas ressalvas pela Oppen. Pedimos que olhem com atenção.
A5: Revisão Interna | B5: Controle de revisões OPPEN
A6: Necessário ajuste | B6: A pergunta necessita de ajustes, o cliente deverá descrever o ajuste na coluna Comentários_FIS
A7: Exclusão | B7: A pergunta será excluída por sugestão do cliente.
A8: Aprovado | B8: A pergunta foi aprovada pelo cliente, após esse status ela não deverá ser modificada, salvo exceções.

Sheet Questionário
A1: COD_FINAL | B1: Descritor | C1: Triangulação | D1: Página | E1: Variável | F1: Comentários_Oppen/Histórico | G1: Pergunta adaptada | H1: Instrução | I1: Cod | J1: Alternativas de resposta | K1: Questão dependente | L1: Opção | M1: Pré-condição | N1: Tipo de resposta | O1: Validação | P1: Restrições | Q1: Ajustes na programação | R1: Descrição | S1: Observações para equipe de programação | T1: Status | U1: Comentários Mariana | V1: Comentários Mona | W1: Comentários Luciana | X1: Comentários Joao | Y1: Comentários Aline
A2: Não se aplica | D2: 1 | E2: abordagem | F2: Oppen 01.09: Texto inserido de acordo com a versão do dia 29.08.23 enviada ao IU. Oppen 24.10: versão atualizada após correção da Maju, enviada pelo IU. | G2: Olá! Você é um dos profissionais mais relevantes para a gestão da política educacional de seu estado e conhece a parceria da Secretaria com o Instituto Unibanco no Programa Jovem de Futuro. Além disso, conhece, usa e compõe o Circuito de Gestão. Este questionário tem como objetivo levantar informações sobre a implementação do Circuito de Gestão na rede estadual de educação em que você atua. As informações coletadas vão servir ao aprimoramento dessa implementação. Você encontrará, aqui, questões que solicitam dados pessoais: primeiro nome, faixa etária, sexo, cargo, local de trabalho e tempo de experiência na Secretaria Estadual de Educação e no seu cargo. Também há questões sobre a implementação dos processos e protocolos do Circuito de Gestão. A necessidade de dados pessoais se justifica pelo interesse de segmentar apoios a partir de uma análise demográfica e de perfil profissional. Necessário declarar que a pesquisa atende as exigências da Lei Geral de Proteção De Dados Pessoais (Lei nº 13.709/2018), além de seguir os princípios éticos que sustentam e orientam a parceria entre a Secretaria e o Instituto Unibanco. Qualquer divulgação só ocorrerá com aprovação das lideranças da secretaria e os dados serão agregados, não permitindo qualquer identificação do respondente. Contamos com sua colaboração em responder este questionário a partir de sua experiência e reflexão sobre o Circuito de Gestão e agradecemos imensamente a sua dedicação de tempo respondê-lo. | N2: note | P2: vazio
D3: 2 | E3: consent | F3: Oppen 01.09: Texto inserido de acordo com a versão do dia 29.08.23 enviada ao IU. | G3: Algumas garantias devem ser compartilhadas com você. Todos os dados pessoais fornecidos serão tratados com segurança, de acordo com a Lei Geral de Proteção De Dados Pessoais (Lei nº 13.709/2018). Os dados que você fornecer serão divulgados de forma agregada e nenhuma das suas respostas será divulgada individualmente. As informações serão utilizadas somente para os fins desta pesquisa e serão compartilhadas com o Instituto Unibanco e seus parceiros. Por fim, declaramos que todos os dados fornecidos por você serão armazenados apenas pelo tempo necessário para que as finalidades informadas sejam atingidas ou em conformidade com obrigações legais e regulatórias. Sendo assim, ao aceitar participar desta pesquisa, você declara estar ciente que: - Eventuais informações fornecidas não permitirão a sua identificação, exceto para a equipe de pesquisa e para o Instituto Unibanco; - A divulgação de informações apenas acontecerá de forma agregada e/ou anonimizada e só será feita entre as instituições, profissionais e parceiros do estudo; - O seu consentimento é concedido para que a Oppen Social (i) colete dados pessoais fornecidos voluntariamente no questionário; (ii) utilize esses dados com o objetivo de caracterizar o perfil dos atores envolvidos na área de educação do estado; e (iii) compartilhe os dados pessoais com terceiros contratados para a prestação dos serviços da pesquisa. - Você tem direito de solicitar acesso, retificação ou eliminação dos seus dados pessoais tratados pela Oppen, além de poder revogar o seu consentimento a qualquer tempo, sem que isso lhe traga qualquer penalidade ou prejuízo. - Os resultados desta pesquisa serão divulgados de forma agregada e anonimizada para a Secretaria de Educação do seu estado no contexto da implementação do Jovem de Futuro e do Circuito de Gestão. Ao continuar com esse questionário, você concorda com o disposto neste Aviso. | I3: 1 | J3: Continuar. | N3: select_one | O3: obrigatoria | P3: vazio | W3: Quando o formulário estiver concluído, a parte do pré-teste será retirada das orientações, correto? Roda de conversa só está prevista para a fase do pré-teste, certo? Penso que devemos trabalhar sempre com a nomenclatura de Secretaria de Estado, pois o IU não tem parceria com Secretaria Municipal
I4: 2 | J4: Encerrar.
D5: 3 | E5: intro | F5: Oppen 01.09: Texto inserido de acordo com a versão do dia 29.08.23 enviada ao IU. | G5: Para participar dessa pesquisa, pedimos que leve em consideração não somente a sua experiência, mas também a de outros profissionais da Regional, da Secretaria e das escolas da sua regional no processo de implementação do Circuito de Gestão, no contexto da parceria com o IU | Jovem de Futuro. Este questionário é composto de 7 seções: 1. Circuito de Gestão na Regional; 2. Apoio da Secretaria à Regional de Ensino; 3. Apoio da Regional ao ACG (ou Superintendente, Supervisor ou Tutor); 4. Apoio do ACG (ou Superintendente, Supervisor ou Tutor) às escolas; 5. Circuito de Gestão nas Escolas; 6. Circuito de Gestão na Secretaria e ações disparadoras; 7. Customização dos Protocolos. Recomendamos que reserve cerca de 60 minutos e tente responder em um ambiente tranquilo e silencioso, a fim de garantir sua total concentração e atenção. Não há tempo máximo para cada pergunta e, caso você precise se ausentar, recomendamos que não feche o link do questionário para não perder o histórico de suas respostas. Caso não se sinta confortavel ou não tenha informações suficientes para responder alguma pergunta, por favor, marque a alternativa "Prefiro não responder (Não sei)". Reforçamos que não exstem respostas certas ou erradas. | H5: Algumas perguntas deste questionário dizem respeito ao profissional da regional responsável por acompanhar a implementação do Circuito de Gestao nas escolas, aqui denominado ACG (Profissional de apoio ao Circuito de Gestão).Sabemos, contudo, que ele recebe denominações distintas nos estados. Ou seja, no Ceará, ele recebe o nome de Superintendente; no Espírito Santo, de Supervisor; em Goiás, de Tutor; e, no Piauí, de Técnico de Ensino ou ACG. | K5: consent | L5: 1 | N5: note | P5: vazio | Q5: Sim | R5: Alterar texto da nota de instrução (coluna H)
D6: 4 | E6: duration | K6: consent | L6: 1 | N6: duration | P6: vazio
D7: 4 | E7: intro_id | G7: Vamos iniciar com algumas perguntas sobre você. | K7: consent | L7: 1 | N7: note | P7: vazio
D8: 4 | E8: nome | G8: Qual seu nome? | H8: Escreva seu primeiro nome. | K8: consent | L8: 1 | N8: texto | O8: obrigatoria | W8: Não devériamos pedir o nome completo?
D9: 4 | E9: fx_etaria | G9: Qual a sua idade? | I9: 1 | J9: Até 24 anos. | K9: consent | L9: 1 | N9: select_one | O9: obrigatoria | P9: vazio
I10: 2 | J10: 25 a 29 anos
I11: 3 | J11: 30 a 34 anos
I12: 4 | J12: 35 a 39 anos
I13: 5 | J13: 40 a 44 anos
I14: 6 | J14: 45 a 49 anos
I15: 7 | J15: 50 a 54 anos
I16: 8 | J16: 55 a 59 anos
I17: 9 | J17: 60 anos ou mais
D18: 4 | E18: sexo | G18: Qual é o seu sexo? | I18: 1 | J18: Masculino. | K18: consent | L18: 1 | N18: select_one | O18: obrigatoria | P18: vazio
I19: 2 | J19: Feminino.
I20: 77 | J20: Prefiro não informar.
D21: 4 | E21: see | G21: Em qual Secretaria Estadual de Educação você está alocado? | I21: 1 | J21: Secretaria Estadual de Educação do Ceará. | K21: consent | L21: 1 | N21: select_one | O21: obrigatoria | P21: vazio
I22: 2 | J22: Secretaria Estadual de Educação do Espírito Santo.
I23: 3 | J23: Secretaria Estadual de Educação de Goiás.
I24: 4 | J24: Secretaria Estadual de Educação do Piauí.
D25: 4 | E25: sre | G25: Por favor, selecione a Regional de Ensino em que você está alocado(a): | J25: LISTA DE REGIONAIS POR UF | K25: consent | L25: 1 | N25: select_one | O25: obrigatoria | P25: vazio
A26: Não se aplica | B26: Não se aplica | D26: 5 | E26: cargo | F26: Oppen 04.09: Importante inserir listagem de cargos, caso essa informação seja relevante. IMPORTANTE: Não está previsto no plano de análise esse tipo de recorte. Devemos prever isso no plano tabular? Esse tipo de análise ficará com IU ou Oppen? | G26: Qual é o seu atual cargo na Regional? | H26: Por favor, digite seu cargo. | K26: consent | L26: 1 | N26: text | O26: obrigatoria | P26: texto
D27: 5 | E27: papel_cdg | F27: Oppen 25.10: Isso não está previsto no plano de análise. | G27: Qual é o seu papel no Circuito de Gestão na Regional? | I27: 1 | J27: Responsável pelo Circuito de Gestão na Regional. | K27: consent | L27: 1 | N27: select_one | O27: obrigatoria | P27: vazio
I28: 2 | J28: Coordenador dos ACGs (ou Supervisores, Superintendentes, Tutores).
I29: 3 | J29: Outro.
D30: 5 | E30: tempo_experiencia_see | G30: Há quanto tempo você implementa o Circuito de Gestão (CdG)? | I30: 1 | J30: Menos de 6 meses. | K30: consent | L30: 1 | N30: select_one | O30: obrigatoria | P30: vazio
I31: 2 | J31: De 6 meses a 1 ano.
I32: 3 | J32: De 2 a 3 anos.
I33: 4 | J33: Mais de 4 anos.
D34: 6 | E34: bloco_1 | G34: BLOCO 1: CIRCUITO DE GESTÃO NA REGIONAL DE ENSINO. Antes de iniciarmos o questionário, é importante lembrarmos quem é o ACG, o profissional da Regional que apoia a implementação do Circuito de Gestão nas escolas. Sabemos que, em cada secretaria, esse profissional tem denominações distintas: no Ceará, é o Superintendente; no Espírito Santo, é o Supervisor; em Goiás, é o Tutor; e, no Piauí é o Técnico de Ensino ou ACG. Vamos começar com algumas perguntas sobre as etapas de PACTUAÇÃO DE METAS e de PLANEJAMENTO na Regional de Ensino. | K34: consent | L34: 1 | N34: note | P34: vazio
A35: E1D1_5 | B35: As metas pactuadas são compartilhadas com os profissionais das escolas e das regionais. | C35: 1;2;3;4;5 | D35: 6 | E35: V01 | F35: Oppen 09.10: Item idêntico ao Questionário do ACG | G35: Nos últimos 12 meses, você participou de algum encontro de apresentação das metas da Secretaria, das Regionais e das Escolas para as regionais? | H35: Lembrando que a meta é calculada a partir do IDEB*, uma combinação entre os resultados de Língua Portuguesa e Matemática dos estudantes nas avaliações externas estaduais e do fluxo dos estudantes (taxa de aprovação). | I35: 1 | J35: Sim. | K35: consent | L35: 1 | N35: select_one | O35: obrigatoria | P35: vazio
I36: 2 | J36: Não.
A37: E1D1_5 | B37: As metas pactuadas são compartilhadas com os profissionais das escolas e das regionais. | C37: 1;2;3;4;5 | D37: 6 | E37: V02 | F37: Oppen 09.10: Item idêntico ao Questionário do ACG | G37: Você conhece a meta da sua regional? | I37: 1 | J37: Sim. | K37: consent | L37: 1 | N37: select_one | O37: obrigatoria | P37: vazio
I38: 2 | J38: Não.
I39: 77 | J39: A Regional não tem meta.
A40: E1D1_5 | B40: As metas pactuadas são compartilhadas com os profissionais das escolas e das regionais. | D40: 6 | E40: V03 | G40: Você conhece as metas das escolas da sua Regional? | I40: 1 | J40: Sim. | K40: consent | L40: 1 | N40: select_one | O40: obrigatoria | P40: vazio
...

Sheet Opções - Tipo de Resposta
A1: Lista de opções mais frequentes | E1: Lista Geral
A2: Escolha Única, Vertical | B2: select_one | E2: text
A3: Múltipla escolha | B3: select_multiple | E3: integer
A4: Numérica | B4: integer | E4: decimal
A5: String | B5: text | E5: select_one
A6: Texto e Número | B6: decimal | E6: select_multiple
A7: Data | B7: date | E7: geopoint
A8: E-mail | B8: text | E8: geoshape
A9: - | B9: note | E9: geotrace
E10: barcode
E11: date
E12: datetime
E13: image
E14: audio
E15: video
E16: file
E17: note
E18: phonenumber
E19: comments
E20: calculate
E21: calculate_here
... E25: sensor_statistic pct_movement_between

Sheet Opções - Restrições
A1: Lista de restrições | B1: Opção de restrição
A2: Texto | B2: texto
A3: Número | B3: número
A4: Texto+Número | B4: texto+número
A5: Data | B5: data
A6: Email | B6: email
A7: Vazio | B7: vazio

Sheet Instruções
A1: Novas colunas | B1: Instruções
A2: Página | B2: Preencher sempre com números inteiros. De maneira crescente (1 até 20, por exemplo).
A3: Questão dependente | B3: Usar quando houver somente uma questão no fluxo que depende de outra. Exemplo: Se V004 depende da V003, quando a opção for 1. Escrever neste campo somente V003 e colocar 1 na coluna "Opção".
A4: Opção | B4: Usar quando houver somente uma questão no fluxo que depende de outra. Exemplo: Se V004 depende da V003, quando a opção for 1. Escrever neste campo somente o valor 1.
A5: Pre-condicao | B5: Usar quando houver mais de uma questão ou mais de uma opção de questão dependente. Exemplo, Se V004 depende de V003 quando as opções são 1, 2 ou 3. Ou se V004, depende de V003 = 1 e/ou V002 = 2
A6: Tipo de resposta | B6: Escolher qual o tipo de questão será usada. As opções disponíveis se encontram na aba Opções - Tipo de Resposta
A7: Restrição | B7: Usar quando a questão for do tipo "text", na qual é possível escolher se o campo aceita só texto e número, ou somente número, etc. Caso o campo não tenha restrição de texto, escolher a opção Vazio.

Sheet Checagem_Referencial
A1: COD_FINAL | B1: Descritor | C1: Triangulação | D1: Checagem
A2: E1D1_1 | B2: A Secretaria Estadual de Educação revisa, anualmente, as metas para escolas e regionais a partir dos resultados das avaliações externas | C2: 1;2 | D2: =IFERROR(IF(VLOOKUP(A2,Questionário!A:A,1,FALSE)=A2, "Ok","Ausente"), "Ausente") -> Ok
A3: E1D1_2 | B3: A Secretaria Estadual de Educação define escolas prioritárias a partir das metas estabelecidas. | C3: 1;2 | D3: =IFERROR(IF(VLOOKUP(A3,Questionário!A:A,1,FALSE)=A3, "Ok","Ausente"), "Ausente") -> Ok
A4: E1D1_4 | B4: As escolas prioritárias recebem metas maiores e mais ousadas. | C4: 1;2;3 | D4: =IFERROR(IF(VLOOKUP(A4,Questionário!A:A,1,FALSE)=A4, "Ok","Ausente"), "Ausente") -> Ok
A5: E1D1_5 | B5: As metas pactuadas são compartilhadas com os profissionais das escolas e das regionais. | C5: 1;2;3;4;5 | D5: =IFERROR(IF(VLOOKUP(A5,Questionário!A:A,1,FALSE)=A5, "Ok","Ausente"), "Ausente") -> Ok
A6: E1D2_6 | B6: A equipe técnica da Regional utiliza as metas da regional e das escolas sob sua jurisdição para o planejamento de suas ações. | C6: 2;3 | D6: =IFERROR(IF(VLOOKUP(A6,Questionário!A:A,1,FALSE)=A6, "Ok","Ausente"), "Ausente") -> Ok
A7: E1D2_7 | B7: A equipe escolar conhece suas metas. | C7: 2;3;4 | D7: =IFERROR(IF(VLOOKUP(A7,Questionário!A:A,1,FALSE)=A7, "Ok","Ausente"), "Ausente") -> Ok
A8: E1D2_10 | B8: A equipe técnica da Regional reconhece a importância da identificação das escolas prioritárias como estratégia de enfrentamento das desigualdades entre as escolas, oferecendo apoio e ações diferenciadas. | C8: 2;3 | D8: =IFERROR(IF(VLOOKUP(A8,Questionário!A:A,1,FALSE)=A8, "Ok","Ausente"), "Ausente") -> Ok
A9: E1D4_15 | B9: A Regional conduz o processo de pactuação de metas com seu grupo de escolas, afim de promover o engajamento. | C9: 2;3 | D9: =IFERROR(IF(VLOOKUP(A9,Questionário!A:A,1,FALSE)=A9, "Ok","Ausente"), "Ausente") -> Ok
A10: E2D1_1 | B10: A Secretaria Estadual de Educação define os objetivos estratégicos para nortear o planejamento anual. | C10: 1;2 | D10: =IFERROR(IF(VLOOKUP(A10,Questionário!A:A,1,FALSE)=A10, "Ok","Ausente"), "Ausente") -> Ok
A11: E2D1_3 | B11: A Secretaria Estadual de Educação compartilha o calendário anual do CdG com a rede. | C11: 1;2;3;4 | D11: =IFERROR(IF(VLOOKUP(A11,Questionário!A:A,1,FALSE)=A11, "Ok","Ausente"), "Ausente") -> Ok
A12: E2D1_4 | B12: A Secretaria Estadual de Educação insere seu plano de ação no Sistema de Gestão para o Avanço Contínuo da Educação (Sigae) no prazo estipulado pelo cronograma pactuado com a rede. | C12: 1;2;3;4;5 | D12: =IFERROR(IF(VLOOKUP(A12,Questionário!A:A,1,FALSE)=A12, "Ok","Ausente"), "Ausente") -> Ok | E12: Teve um item excluído após revisão do IU em 20.10
A13: E2D1_5 | B13: As Regionais inserem seus planos de ação no Sistema de Gestão para o Avanço Contínuo da Educação (Sigae) no prazo estipulado pelo cronograma pactuado com a rede. | C13: 1;2;3;4;5 | D13: =IFERROR(IF(VLOOKUP(A13,Questionário!A:A,1,FALSE)=A13, "Ok","Ausente"), "Ausente") -> Ok
A14: E2D1_8 | B14: O plano de ação das Regionais é orientado pelos objetivos estratégicos estabelecidos pela Secretaria Estadual de Educação. | C14: 1;2;5 | D14: =IFERROR(IF(VLOOKUP(A14,Questionário!A:A,1,FALSE)=A14, "Ok","Ausente"), "Ausente") -> Ok
A15: E2D1_11 | B15: Os planos de ação das Regionais são elaborados com base no diagnóstico feito no ano anterior, com foco nos resultados de aprendizagem e fluxo (aprovação e abandono). | C15: 1;2;3 | D15: =IFERROR(IF(VLOOKUP(A15,Questionário!A:A,1,FALSE)=A15, "Ok","Ausente"), "Ausente") -> Ok
A16: E2D1_12 | B16: Os planos de ação das Escolas são elaborados com base no diagnóstico feito no ano anterior, com foco nos resultados de aprendizagem e fluxo (aprovação e abandono). | C16: 2;3;4 | D16: =IFERROR(IF(VLOOKUP(A16,Questionário!A:A,1,FALSE)=A16, "Ok","Ausente"), "Ausente") -> Ok
A17: E2D2_14 | B17: Há profissionais de diferentes áreas da Regional (área financeira, pedagógica, infraestrutura, pessoas, etc.) com atribuições de tarefas e ações no plano de ações das regional. | C17: 1;2;3 | D17: =IFERROR(IF(VLOOKUP(A17,Questionário!A:A,1,FALSE)=A17, "Ok","Ausente"), "Ausente") -> Ok
A18: E2D2_16 | B18: Há profissionais nas Regionais que apoiam os ACGs na realização das devolutivas, reuniões de trabalho e visitas técnicas para elaboração do plano de ação das escolas sob sua jurisdição. | C18: 2;3 | D18: =IFERROR(IF(VLOOKUP(A18,Questionário!A:A,1,FALSE)=A18, "Ok","Ausente"), "Ausente") -> Ok
A19: E2D3_17 | B19: A Secretaria Estadual de Educação possui equipes responsáveis por zelar pelo cronograma, acompanhar o processo de planejamento e fornecer orientações para os profissionais das regionais; | C19: 1;2;3 | D19: =IFERROR(IF(VLOOKUP(A19,Questionário!A:A,1,FALSE)=A19, "Ok","Ausente"), "Ausente") -> Ausente | E19: Excluído após revisão do IU em 17.10.
A20: E2D3_18 | B20: As Regionais possuem equipes responsáveis por zelar pelo cronograma, acompanhar o processo de planejamento e fornecer orientações para os profissionais das escolas. | C20: 1;2 | D20: =IFERROR(IF(VLOOKUP(A20,Questionário!A:A,1,FALSE)=A20, "Ok","Ausente"), "Ausente") -> Ausente | E20: Excluído após revisão do IU em 17.10.
A21: E2D3_19 | B21: A Secretaria Estadual de Educação elabora um plano de priorização que identifica regionais, ACGs, escolas, e estudantes que precisam de maior apoio, alinhado aos objetivos estabelecidos pela rede. | C21: 1;2;3;4 | D21: =IFERROR(IF(VLOOKUP(A21,Questionário!A:A,1,FALSE)=A21, "Ok","Ausente"), "Ausente") -> Ok
A22: E2D3_20 | B22: As Regionais elaboram planos de priorização que identificam ACGs, escolas e estudantes que precisam de maior apoio, alinhado aos objetivos estabelecidos pela rede. | C22: 1;2 | D22: =IFERROR(IF(VLOOKUP(A22,Questionário!A:A,1,FALSE)=A22, "Ok","Ausente"), "Ausente") -> Ok
A23: E2D3_21 | B23: Há ACGs suficientes para acompanhar o processo de planejamento das escolas da regional. | C23: 1;2;3;4 | D23: =IFERROR(IF(VLOOKUP(A23,Questionário!A:A,1,FALSE)=A23, "Ok","Ausente"), "Ausente") -> Ok
A24: E2D4_22 | B24: A Secretaria Estadual de Educação disponibiliza informações sobre os programas, projetos, ações e recursos para que as instâncias considerem na elaboração de seus planos. | C24: 1;2;3;4;5 | D24: =IFERROR(IF(VLOOKUP(A24,Questionário!A:A,1,FALSE)=A24, "Ok","Ausente"), "Ausente") -> Ok
A25: E2D4_23 | B25: A Secretaria Estadual de Educação realiza a análise dos dados provenientes dos planos de ação das regionais, de acordo com os objetivos estratégicos traçados, prepara e realiza as devolutivas para o aprimoramento dos planos de ação das regionais . | C25: 1;2 | D25: =IFERROR(IF(VLOOKUP(A25,Questionário!A:A,1,FALSE)=A25, "Ok","Ausente"), "Ausente") -> Ok
A26: E2D4_24 | B26: O ACG apoia a equipe gestora na elaboração do plano de ação da escola. | C26: 2;3;4 | D26: =IFERROR(IF(VLOOKUP(A26,Questionário!A:A,1,FALSE)=A26, "Ok","Ausente"), "Ausente") -> Ok
A27: E2D4_25 | B27: O ACG analisa o plano de ação das escolas que acompanha quanto à coerência com os objetivos estratégicos e entre os problemas, causas e ações e realiza as devolutivas para o aprimoramento dos planos de ação. | C27: 1;2;3 | D27: =IFERROR(IF(VLOOKUP(A27,Questionário!A:A,1,FALSE)=A27, "Ok","Ausente"), "Ausente") -> Ok
A28: E2D4_28 | B28: As Regionais utilizam os insumos dos planos das escolas sob sua jurisdição para aprimorar seus próprios planos de ação. | C28: 2;3;4 | D28: =IFERROR(IF(VLOOKUP(A28,Questionário!A:A,1,FALSE)=A28, "Ok","Ausente"), "Ausente") -> Ok
A29: E2D5_29 | B29: A Secretaria Estadual de Educação fez customizações em ao menos um processo da etapa de planejamento (adaptações nos protocolos, indicadores específicos, formulários para registro de informações, roteiros de análise e de orientação e sistematização das atividades, instruções para o uso do sistema de informações). | C29: 1;2;3 | D29: =IFERROR(IF(VLOOKUP(A29,Questionário!A:A,1,FALSE)=A29, "Ok","Ausente"), "Ausente") -> Ok
A30: E2D5_30 | B30: As Regionais fizeram customizações em ao menos um processo da etapa de planejamento (adaptações nos protocolos, indicadores específicos, formulários para registro de informações, roteiros de análise e de orientação e sistematização das atividades, instruções para o uso do sistema de informações) | C30: 2;3 | D30: =IFERROR(IF(VLOOKUP(A30,Questionário!A:A,1,FALSE)=A30, "Ok","Ausente"), "Ausente") -> Ok
A31: E3D1_2 | B31: As equipes escolares executam as tarefas previstas nos planos de ação dentro dos prazos. | C31: 2;3;4;5 | D31: =IFERROR(IF(VLOOKUP(A31,Questionário!A:A,1,FALSE)=A31, "Ok","Ausente"), "Ausente") -> Ausente | E31: Excluído após revisão do IU em 17.10.
A32: E3D1_3 | B32: As equipes das Regionais executam as tarefas previstas nos planos de ação dentro dos prazos. | C32: 1;2;3;5 | D32: =IFERROR(IF(VLOOKUP(A32,Questionário!A:A,1,FALSE)=A32, "Ok","Ausente"), "Ausente") -> Ok
A33: E3D1_5 | B33: As equipes das Regionais monitoram a execução de seus planos de ação e realizam ajustes pontuais quando necessário. | C33: 1;2;3;5 | D33: =IFERROR(IF(VLOOKUP(A33,Questionário!A:A,1,FALSE)=A33, "Ok","Ausente"), "Ausente") -> Ok
A34: E3D1_7 | B34: A equipe técnica da Secretaria Estadual de Educação insere informações sobre a execução das ações do seu plano de ação no Sistema de Gestão para o Avanço Contínuo da Educação (Sigae) dentro do prazo estipulado no cronograma pactuado pela rede. | C34: 1;2 | D34: =IFERROR(IF(VLOOKUP(A34,Questionário!A:A,1,FALSE)=A34, "Ok","Ausente"), "Ausente") -> Ausente | E34: Excluído após revisão do IU em 20.10
A35: E3D1_8 | B35: As equipes das Regionais inserem informações sobre a execução das tarefas e ações no Sistema de Gestão para o Avanço Contínuo da Educação (Sigae) dentro do prazo estipulado no cronograma pactuado pela rede. | C35: 1;2;5 | D35: =IFERROR(IF(VLOOKUP(A35,Questionário!A:A,1,FALSE)=A35, "Ok","Ausente"), "Ausente") -> Ok
A36: E3D1_9 | B36: As equipes escolares inserem informações sobre frequências, notas e aulas dadas no sistema da própria Secretaria dentro do prazo estipulado no cronograma pactuado pela rede. | C36: 1;2;3;4 | D36: =IFERROR(IF(VLOOKUP(A36,Questionário!A:A,1,FALSE)=A36, "Ok","Ausente"), "Ausente") -> Ok
A37: E3D2_12 | B37: Os profissionais com atribuições de ações e tarefas no plano de ação da Regional se sentem responsáveis pela sua realização e monitoramento. | C37: 2 | D37: =IFERROR(IF(VLOOKUP(A37,Questionário!A:A,1,FALSE)=A37, "Ok","Ausente"), "Ausente") -> Ok
A38: E3D2_14 | B38: A equipe gestora da Secretaria Estadual de Educação acompanha a execução do seu plano de ação. | C38: 1;2 | D38: =IFERROR(IF(VLOOKUP(A38,Questionário!A:A,1,FALSE)=A38, "Ok","Ausente"), "Ausente") -> Ausente | E38: Excluído após revisão do IU em 17.10.
A39: E3D2_16 | B39: A equipe gestora da Regional acompanha a execução do seu plano de ação. | C39: 2;3 | D39: =IFERROR(IF(VLOOKUP(A39,Questionário!A:A,1,FALSE)=A39, "Ok","Ausente"), "Ausente") -> Ok
A40: E3D2_17 | B40: A equipe gestora da Regional apoia os profissionais responsáveis pelas tarefas e ações de seu palno de ação. | C40: 2;3 | D40: =IFERROR(IF(VLOOKUP(A40,Questionário!A:A,1,FALSE)=A40, "Ok","Ausente"), "Ausente") -> Ausente | E40: Excluído após revisão do IU em 24.10.
...
