Workbook
Name Escolha_Única__Vertical: 'Opções - Tipo de Resposta'!$A$3:$A$6

Sheet Status_Legenda
A1: Status | B1: Descrição
A2: Em elaboração | B2: A pergunta está em elaboração, não modifique o enunciado.
A3: Disponível para revisão | B3: A pergunta está disponível para revisão, não foram feitas ressalvas pela Oppen.
A4: Disponível para revisão com ressalvas | B4: A pergunta está disponível para revisão com ressalvas, foram feitas ressalvas pela Oppen. Pedimos que olhem com atenção.
A5: Revisão Interna | B5: Controle de revisões OPPEN
A6: Necessário ajuste | B6: A pergunta necessita de ajustes, o cliente deverá descrever o ajuste na coluna Comentários_FIS
A7: Exclusão | B7: A pergunta será excluída por sugestão do cliente.
A8: Aprovado | B8: A pergunta foi aprovada pelo cliente, após esse status ela não deverá ser modificada, salvo exceções.

Sheet LEIA-ME
C1: INSTRUÇÕES SOBRE O ARQUIVO
B4: Aba - Questionário | I4: Aba Plano Tabular
B5: Nome da coluna | C5: Descrição | E5: Status (Coluna Q) | F5: Descrição | I5: Item | J5: Descrição
B6: CODFINAL | C6: Código numérico correspondente ao código de identificação do descritor. | E6: Em elaboração | F6: A pergunta está em elaboração, não modifique o enunciado. | I6: Indicador | J6: Indicador do estudo à que a questão elaborada estará medindo.
B7: Página | C7: Cada uma das folhas de um questionário impresso e/ou seções divisórias de um questionário online. | E7: Disponível para revisão | F7: A pergunta está disponível para revisão, não foram feitas ressalvas pela Oppen. | I7: Fonte | J7: Fonte de inspiração da pergunta.
B8: Variável | C8: Nome da variável correspondente à pergunta. | E8: Disponível com ressalvas para a revisão | F8: A pergunta está disponível para revisão com ressalvas, foram feitas ressalvas pela Oppen. Pedimos que olhem com atenção. | I8: cod_item | J8: Nome dado à variável na base de dados. .
B9: Comentários_Oppen/Histórico | C9: Destina-se aos diálogos internos entre a equipe da Oppen acerca do material que está sendo elaborado. | E9: Revisão Interna | F9: Controle de revisões OPPEN | I9: item | J9: Perguntas elaboradas pela equipe da Oppen Social ou propostas pelo cliente.
B10: Pergunta adaptada | C10: Perguntas elaboradas pela equipe da Oppen Social ou propostas pelo cliente. | E10: Necessário ajuste | F10: A pergunta necessita de ajustes, o cliente deverá descrever o ajuste na coluna Comentários_FIS | I10: cod_resp | J10: Código numérico correspondente a alternativa de resposta.
B11: Nota explicativa | C11: Complementos explicativos sobre as perguntas adaptadas para os respondentes do questionário. | E11: Exclusão | F11: A pergunta será excluída por sugestão do cliente. | I11: alternativa de resposta | J11: Para perguntas fechadas, as alternativas pré-estabelecidas são deixadas aqui. Para o caso de perguntas abertas, há um espaço para a resposta.
B12: Cod | C12: Código numérico correspondente a alternativa de resposta. | E12: Sugestão de Exclusão | F12: A Oppen sugere pela exclusão da pergunta. | I12: justificativa | J12: Razão que orienta a elaboração da pergunta para este questionário.
B13: Alternativas de resposta | C13: Para perguntas fechadas, as alternativas pré-estabelecidas são deixadas aqui. Para o caso de perguntas abertas, há um espaço para a resposta. | E13: Aprovado | F13: A pergunta foi aprovada pelo cliente, após esse status ela não deverá ser modificada, salvo exceções.
B14: Questão dependente | C14: Especificação de qual será a próxima pergunta a ser apresentada ao entrevistado com base na resposta dada na pergunta anterior.
B15: Opção | C15: Sinalização da alternativa de resposta que condiciona a abertura de pergunta.
B16: Pré-condição | C16: Espaço destinado para sinalizar em quais situações a pergunta deverá abrir, em casos de mais de uma regra de filtro.
B17: Tipo de resposta | C17: Diz respeito aos formatos de resposta: escolha única, múltipla escolha, numérica, texto, texto e número, data e e-mail.
B18: Validação (Regra de Programação) | C18: Espaço destinado para especificar quais respostas são validas para a pergunta. Por exemplo, casos em que a pergunta tem o formato múltipla escolha, mas se registrado "Prefere não responder", não poderá registrar outra.
B19: Restrição | C19: Novamente, diz respeito ao formato de resposta: texto, número, texto e número, data, e-mail e vazio. Vazio se refere à perguntas de escolha única ou múltipla escolha.
B20: Observações | C20: Espaço para comentários ou especificações sobre as perguntas.
B21: Status | C21: Diz respeito ao andamento da elaboração da pergunta: Em elaboração, Disponível para revisão, Disponível para revisão com ressalvas, Necessário ajuste, Exclusão e Aprovado.
B22: Comentários | C22: Espaço para deixar as impressões sobre a pergunta e sugestões.

Sheet Opções - Tipo de Resposta
A1: Lista de opções mais frequentes | E1: Lista Geral
A2: Escolha Única, Vertical | B2: select_one | E2: text
A3: Múltipla escolha | B3: select_multiple | E3: integer
A4: Numérica | B4: integer | E4: decimal
A5: String | B5: text | E5: select_one
A6: Texto e Número | B6: decimal | E6: select_multiple
A7: Data | B7: date | E7: geopoint
A8: E-mail | B8: text | E8: geoshape
A9: - | B9: note | E9: geotrace
E10: barcode
E11: date
E12: datetime
E13: image
E14: audio
E15: video
E16: file
E17: note
E18: phonenumber
E19: comments
E20: calculate
E21: calculate_here
... E25: sensor_statistic pct_movement_between

Sheet Opções - Restrições
A1: Lista de restrições | B1: Opção de restrição
A2: Texto | B2: texto
A3: Número | B3: número
A4: Texto+Número | B4: texto+número
A5: Data | B5: data
A6: Email | B6: email
A7: Vazio | B7: vazio

Sheet Instruções
A1: Novas colunas | B1: Instruções
A2: Página | B2: Preencher sempre com números inteiros. De maneira crescente (1 até 20, por exemplo).
A3: Questão dependente | B3: Usar quando houver somente uma questão no fluxo que depende de outra. Exemplo: Se V004 depende da V003, quando a opção for 1. Escrever neste campo somente V003 e colocar 1 na coluna "Opção".
A4: Opção | B4: Usar quando houver somente uma questão no fluxo que depende de outra. Exemplo: Se V004 depende da V003, quando a opção for 1. Escrever neste campo somente o valor 1.
A5: Pre-condicao | B5: Usar quando houver mais de uma questão ou mais de uma opção de questão dependente. Exemplo, Se V004 depende de V003 quando as opções são 1, 2 ou 3. Ou se V004, depende de V003 = 1 e/ou V002 = 2
A6: Tipo de resposta | B6: Escolher qual o tipo de questão será usada. As opções disponíveis se encontram na aba Opções - Tipo de Resposta
A7: Restrição | B7: Usar quando a questão for do tipo "text", na qual é possível escolher se o campo aceita só texto e número, ou somente número, etc. Caso o campo não tenha restrição de texto, escolher a opção Vazio.

Sheet Questionário
A1: COD_FINAL | B1: Descritor | C1: Página | D1: Variável | E1: Comentários_Oppen/Histórico | F1: Pergunta adaptada | G1: Instrução | H1: Cod | I1: Alternativas de resposta | J1: Questão dependente | K1: Opção | L1: Pré-condição | M1: Tipo de resposta | N1: Validação | O1: Restrições | P1: Ajustes na programação | Q1: Descrição | R1: Observações para equipe de programação | S1: Comentários Mariana
A2: Não se aplica | B2: Não se aplica | C2: 1 | D2: tela1 | E2: Oppen 01.09: Texto inserido de acordo com a versão do dia 29.08.23 enviada ao IU. Texto atualizado em 23.10 atendendo o pedido do IU. | F2: AVISO DE PRIVACIDADE Olá! Você é um dos atores mais relevantes para a gestão da política educacional de seu estado e conhece a parceria da Secretaria com o Instituto Unibanco no Programa Jovem de Futuro. Além disso, conhece, usa e compõe o circuito de gestão. Este questionário tem como objetivo levantar informações sobre a implementação do Circuito de Gestão na rede estadual de educação em que você atua. As informações coletadas vão servir ao aprimoramento dessa implementação. Você encontrará, aqui, questões que solicitam dados pessoais: primeiro nome, faixa etária, sexo, cargo, local de trabalho e tempo de experiência na Secretaria Estadual de Educação e no seu cargo. Também há questões sobre a implementação dos processos e protocolos do Circuito de Gestão. A necessidade de dados pessoais se justifica pelo interesse de segmentar apoios a partir de uma análise demográfica e de perfil profissional. Necessário declarar que a pesquisa atende as exigências da Lei Geral de Proteção De Dados Pessoais (Lei nº 13.709/2018), além de seguir os princípios éticos que sustentam e orientam a parceria entre a Secretaria e o Instituto Unibanco. Qualquer divulgação só ocorrerá com aprovação das lideranças da secretaria e os dados serão agregados, não permitindo qualquer identificação do respondente. Contamos com sua colaboração em responder este questionário a partir de sua experiência e reflexão sobre o circuito de gestão e agradecemos imensamente a sua dedicação de tempo respondê-lo. | M2: note | O2: vazio
A3: Não se aplica | B3: Não se aplica | C3: 2 | D3: consent | E3: Oppen 01.09: Texto inserido de acordo com a versão do dia 29.08.23 enviada ao IU. Texto atualizado em 23.10 atendendo o pedido do IU. | F3: Algumas garantias devem ser compartilhadas com você. Todos os dados pessoais fornecidos serão tratados com segurança, de acordo com a Lei Geral de Proteção De Dados Pessoais (Lei nº 13.709/2018). Os dados que você fornecer serão divulgados de forma agregada e nenhuma das suas respostas será divulgada individualmente. As informações serão utilizadas somente para os fins desta pesquisa e serão compartilhadas com o Instituto Unibanco e seus parceiros. Por fim, declaramos que todos os dados fornecidos por você serão armazenados apenas pelo tempo necessário para que as finalidades informadas sejam atingidas ou em conformidade com obrigações legais e regulatórias. Sendo assim, ao aceitar participar desta pesquisa, você declara estar ciente que: - Eventuais informações fornecidas não permitirão a sua identificação, exceto para a equipe de pesquisa bem como para o Instituto Unibanco; - A divulgação de informações apenas acontecerá de forma agregada e/ou anonimizada e só será feita entre as instituições, profissionais e parceiros do estudo; - O seu consentimento é concedido para que a Oppen Social (i) colete dados pessoais fornecidos voluntariamente no questionário; (ii) utilize esses dados com o objetivo de caracterizar o perfil dos atores envolvidos na área de educação do estado; e (iii) compartilhe os dados pessoais com terceiros contratados para a prestação dos serviços da pesquisa. - Você tem direito de solicitar acesso, retificação ou eliminação dos seus dados pessoais tratados pela Oppen, além de poder revogar o seu consentimento a qualquer tempo, sem que isso lhe traga qualquer penalidade ou prejuízo. - Os resultados desta pesquisa serão divulgados de forma agregada e anonimizada para a Secretaria de Educação do seu estado no contexto da implementação do Jovem de Futuro e do Circuito de Gestão. Ao continuar com esse questionário, você concorda com o disposto neste Aviso. | H3: 1 | I3: Continuar. | M3: select_one | N3: obrigatoria | O3: vazio
H4: 2 | I4: Encerrar.
A5: Não se aplica | B5: Não se aplica | C5: 3 | D5: duration | J5: consent | K5: 1 | M5: duration | O5: vazio
C6: 3 | D6: intro_geral | F6: Para participar dessa pesquisa, pedimos que leve em consideração tanto a sua experiência quanto a de outros profissionais da sua Secretaria na implementação do Circuito da Gestão (CdG), no contexto da parceria com o Instituto Unibanco, ao longo dos últimos 12 meses. Recomendamos que reserve cerca de 60 minutos e tente responder em um ambiente tranquilo e silencioso, a fim de garantir sua total concentração e atenção. Não há tempo máximo para cada pergunta e, caso você precise se ausentar, recomendamos que não feche o link do questionário para não perder o histórico de suas respostas. Caso você não se sinta confortável para responder a alguma pergunta, selecione a alternativa "Prefiro não responder (Não sei)". | J6: consent | K6: 1 | M6: note | N6: obrigatoria | O6: vazio
A7: Não se aplica | B7: Não se aplica | C7: 3 | D7: intro_id | F7: Vamos iniciar com algumas perguntas sobre você. | J7: consent | K7: 1 | M7: note | O7: vazio
A8: Não se aplica | B8: Não se aplica | C8: 3 | D8: nome | F8: Qual seu nome? | G8: Por favor, escreva seu primeiro nome. | J8: consent | K8: 1 | M8: text | N8: obrigatoria | O8: texto
A9: Não se aplica | B9: Não se aplica | C9: 3 | D9: fx_etaria | F9: Qual a sua idade? | H9: 1 | I9: Até 24 anos. | J9: consent | K9: 1 | M9: select_one | N9: obrigatoria | O9: texto
H10: 2 | I10: 25 a 29 anos
H11: 3 | I11: 30 a 34 anos
H12: 4 | I12: 35 a 39 anos
H13: 5 | I13: 40 a 44 anos
H14: 6 | I14: 45 a 49 anos
H15: 7 | I15: 50 a 54 anos
H16: 8 | I16: 55 a 59 anos
H17: 9 | I17: 60 anos ou mais
A18: Não se aplica | B18: Não se aplica | C18: 3 | D18: sexo | F18: Qual é o seu sexo? | H18: 1 | I18: Masculino. | J18: consent | K18: 1 | M18: select_one | N18: obrigatoria | O18: vazio
H19: 2 | I19: Feminino.
H20: 77 | I20: Prefiro não responder.
A21: Não se aplica | B21: Não se aplica | C21: 3 | D21: see | F21: Em qual Secretaria Estadual de Educação você está alocado? | H21: 1 | I21: Secretaria Estadual de Educação do Ceará. | J21: consent | K21: 1 | M21: select_one | N21: obrigatoria | O21: vazio
H22: 2 | I22: Secretaria Estadual de Educação do Espírito Santo.
H23: 3 | I23: Secretaria Estadual de Educação de Goiás.
H24: 4 | I24: Secretaria Estadual de Educação do Piauí.
A25: Não se aplica | B25: Não se aplica | C25: 3 | D25: cargo | E25: Oppen 04.09: Importante inserir listagem de cargos, caso essa informação seja relevante. IMPORTANTE: Não está previsto no plano de análise esse tipo de recorte. Devemos prever isso no plano tabular? Esse tipo de análise ficará com IU ou Oppen? | F25: Qual é o seu atual cargo na Secretaria? | G25: Por favor, registre seu cargo atual na SEE. | J25: consent | K25: 1 | M25: text | N25: obrigatoria | O25: texto
A26: Não se aplica | B26: Não se aplica | C26: 3 | D26: tempo_experiencia_see | E26: IMPORTANTE: Não está previsto no plano de análise esse tipo de recorte. Devemos prever isso no plano tabular? Esse tipo de análise ficará com IU ou Oppen? | F26: Há quanto tempo você trabalha com o Circuito de Gestão (CdG)? | H26: 1 | I26: Menos de 6 meses. | J26: consent | K26: 1 | M26: select_one | N26: obrigatoria | O26: vazio
H27: 2 | I27: De 6 meses a 1 ano.
H28: 3 | I28: De 2 a 3 anos.
H29: 4 | I29: Mais de 4 anos.
C30: 4 | D30: intro_etapas | F30: Este questionário é composto de 7 seções, que tratam dos seguintes temas: 1. Circuito de Gestão na Secretaria; 2. Apoio da Secretaria às Regionais de Ensino e às Escolas; 3. Circuito de Gestão nas Regionais de Ensino; 4. Apoio das Regionais às escolas; 5. Circuito de Gestão nas Escolas; 6. Adaptações dos Protocolos à realidade da rede; 7. Ações Disparadoras do Circuito de Gestão na Rede. | G30: Sabemos que, em cada secretaria, o profissional que apoia as escolas na implementação do CdG tem denominações distintas: no Ceará, é o Superintendente; no Espírito Santo, é o Supervisor; em Goiás, é o Tutor; e, no Piauí, é o Técnico de Ensino ou ACG. | J30: consent | K30: 1 | M30: note | O30: vazio
A31: Não se aplica | B31: Não se aplica | C31: 5 | D31: intro_metas | F31: BLOCO 1: CIRCUITO DE GESTÃO NA SECRETARIA As próximas perguntas dizem respeito à ETAPA DE PACTUAÇÃO DE METAS do Circuito de Gestão (CdG) na Secretaria. | G31: Para responder este bloco, por favor considere a sua experiência e, sempre que possivel, dos outros profissionais da Secretaria na implementação do Circuito de Gestão na Secretaria. | J31: consent | K31: 1 | M31: note | O31: vazio
A32: E1D1_1 | B32: A Secretaria Estadual de Educação revisa, anualmente, as metas para escolas e regionais a partir dos resultados das avaliações externas. | C32: 5 | D32: V01 | F32: A Secretaria revisa, anualmente, as metas educacionais da rede, das escolas e das regionais, considerando os resultados das avaliações externas e de fluxo dos estudantes (taxas de aprovação) | G32: Por favor, indique o quanto você concorda com a afirmação. Considere como avaliações externas as de âmbito nacional, como o SAEB, e as estaduais como SAEPI, SAEGO, SPAECE e PAEBES. | H32: 1 | I32: 1. Discordo totalmente. | J32: consent | K32: 1 | M32: select_one | N32: obrigatoria | O32: vazio
H33: 2 | I33: 2. Discordo.
H34: 3 | I34: 3. Concordo.
H35: 4 | I35: 4. Concordo totalmente.
H36: 77 | I36: Prefiro não responder (Não sei).
A37: E1D3_11 | B37: A Secretaria Estadual de Educação dispõe de recursos técnicos, como computadores e softwares, adequados para a estimação das metas. | C37: 5 | D37: V02 | E37: Oppen 01.09: Nosso receio de uma pergunta binária para mais de um elemento é que caso a SEE tenha equipamentos não adequados, mas tenha acesso aos softwares e sistemas essa granularidade se perca. | F37: A Secretaria possui os recursos necessários (equipamentos e softwares) para estimar as metas anuais do programa Jovem de Futuro. | G37: Por favor, indique o quanto você concorda com a afirmação. | H37: 1 | I37: 1. Discordo totalmente. | J37: consent | K37: 1 | M37: select_one | N37: obrigatoria | O37: vazio
H38: 2 | I38: 2. Discordo.
H39: 3 | I39: 3. Concordo.
H40: 4 | I40: 4. Concordo totalmente.
...

Sheet Checagem Referencial V29.09
A1: Etapa/Ação | B1: Dimensão | C1: COD_GERAL | D1: Descritor | E1: Triangulação | F1: Checagem | G1: n_itens | H1: Observações Oppen 25.10.23 | I1: Mariana
A2: 1. Pactuação de Metas | B2: Adesão e Rotina | C2: E1D1_1 | D2: A Secretaria Estadual de Educação revisa, anualmente, as metas para escolas e regionais a partir dos resultados das avaliações externas | E2: 1;2 | F2: =IFERROR(IF(VLOOKUP(C2,Questionário!A:A,1,FALSE)=C2,"Ok","Ausente"),"Ausente") -> Ok | G2: =COUNTIF(Questionário!A:A,'Checagem Referencial V29.09'!C2) -> 1
A3: 1. Pactuação de Metas | B3: Adesão e Rotina | C3: E1D1_2 | D3: A Secretaria Estadual de Educação define escolas prioritárias a partir das metas estabelecidas. | E3: 1;2 | F3: =IFERROR(IF(VLOOKUP(C3,Questionário!A:A,1,FALSE)=C3,"Ok","Ausente"),"Ausente") -> Ok | G3: =COUNTIF(Questionário!A:A,'Checagem Referencial V29.09'!C3) -> 1
A4: 1. Pactuação de Metas | B4: Adesão e Rotina | C4: E1D1_3 | D4: A Secretaria Estadual de Educação considera as escolas prioritárias em sua atuação. | E4: 1 | F4: =IFERROR(IF(VLOOKUP(C4,Questionário!A:A,1,FALSE)=C4,"Ok","Ausente"),"Ausente") -> Ok | G4: =COUNTIF(Questionário!A:A,'Checagem Referencial V29.09'!C4) -> 2
A5: 1. Pactuação de Metas | B5: Adesão e Rotina | C5: E1D1_4 | D5: As escolas prioritárias recebem metas maiores e mais ousadas. | E5: 1;2;3 | F5: =IFERROR(IF(VLOOKUP(C5,Questionário!A:A,1,FALSE)=C5,"Ok","Ausente"),"Ausente") -> Ok | G5: =COUNTIF(Questionário!A:A,'Checagem Referencial V29.09'!C5) -> 1
A6: 1. Pactuação de Metas | B6: Adesão e Rotina | C6: E1D1_5 | D6: As metas pactuadas são compartilhadas com os profissionais das escolas e das regionais. | E6: 1;2;3;4;5 | F6: =IFERROR(IF(VLOOKUP(C6,Questionário!A:A,1,FALSE)=C6,"Ok","Ausente"),"Ausente") -> Ok | G6: =COUNTIF(Questionário!A:A,'Checagem Referencial V29.09'!C6) -> 2
A7: 1. Pactuação de Metas | B7: Engajamento | C7: E1D2_9 | D7: A equipe técnica da Secretaria Estadual de Educação reconhece a importância da identificação das escolas prioritárias como estratégia de enfrentamento das desigualdades entre as escolas, oferecendo apoio e ações diferenciadas. | E7: 1;5 | F7: =IFERROR(IF(VLOOKUP(C7,Questionário!A:A,1,FALSE)=C7,"Ok","Ausente"),"Ausente") -> Ok | G7: =COUNTIF(Questionário!A:A,'Checagem Referencial V29.09'!C7) -> 1
A8: 1. Pactuação de Metas | B8: Autonomia | C8: E1D3_11 | D8: A Secretaria Estadual de Educação dispõe de recursos técnicos, como computadores e softwares, adequados para a estimação das metas. | E8: 1 | F8: =IFERROR(IF(VLOOKUP(C8,Questionário!A:A,1,FALSE)=C8,"Ok","Ausente"),"Ausente") -> Ok | G8: =COUNTIF(Questionário!A:A,'Checagem Referencial V29.09'!C8) -> 1
A9: 1. Pactuação de Metas | B9: Autonomia | C9: E1D3_12 | D9: A equipe técnica da Secretaria Estadual de Educação possui profissionais com conhecimento sobre as fórmulas de cálculo e as metodologias de estimação das metas. | E9: 1 | F9: =IFERROR(IF(VLOOKUP(C9,Questionário!A:A,1,FALSE)=C9,"Ok","Ausente"),"Ausente") -> Ok | G9: =COUNTIF(Questionário!A:A,'Checagem Referencial V29.09'!C9) -> 1
A10: 1. Pactuação de Metas | B10: Autonomia | C10: E1D3_13 | D10: A equipe da Secretaria Estadual de Educação revisa de forma autonoma, anualmente, com base nos resultados das avaliações externas, as metas para o estado, as regionais e as escolas. | E10: 1 | F10: =IFERROR(IF(VLOOKUP(C10,Questionário!A:A,1,FALSE)=C10,"Ok","Ausente"),"Ausente") -> Ok | G10: =COUNTIF(Questionário!A:A,'Checagem Referencial V29.09'!C10) -> 1
A11: 1. Pactuação de Metas | B11: Apoio entre Instâncias | C11: E1D4_14 | D11: A Secretaria Estadual de Educação apoia as equipes das Regionais nos processos de pactuaçao das metas com as escolas. | E11: 1;2;3 | F11: =IFERROR(IF(VLOOKUP(C11,Questionário!A:A,1,FALSE)=C11,"Ok","Ausente"),"Ausente") -> Ausente | G11: =COUNTIF(Questionário!A:A,'Checagem Referencial V29.09'!C11) -> 0 | H11: Validada a exclusão em 29.09.23 | I11: ok
A12: 1. Pactuação de Metas | B12: Customização | C12: E1D5_16 | D12: A Secretaria Estadual de Educação adaptou o processo de revisão das metas a sua realidade. | E12: 1 | F12: =IFERROR(IF(VLOOKUP(C12,Questionário!A:A,1,FALSE)=C12,"Ok","Ausente"),"Ausente") -> Ok | G12: =COUNTIF(Questionário!A:A,'Checagem Referencial V29.09'!C12) -> 1
A13: 1. Pactuação de Metas | B13: Customização | C13: E1D5_17 | D13: A Secretaria Estadual de Educação adaptou o processo de compartilhamento de metas com Regionais e Escolas. | E13: 1 | F13: =IFERROR(IF(VLOOKUP(C13,Questionário!A:A,1,FALSE)=C13,"Ok","Ausente"),"Ausente") -> Ok | G13: =COUNTIF(Questionário!A:A,'Checagem Referencial V29.09'!C13) -> 1
A14: 2. Planejamento | B14: Adesão e Rotina | C14: E2D1_1 | D14: A Secretaria Estadual de Educação define os objetivos estratégicos para nortear o planejamento anual. | E14: 1;2 | F14: =IFERROR(IF(VLOOKUP(C14,Questionário!A:A,1,FALSE)=C14,"Ok","Ausente"),"Ausente") -> Ok | G14: =COUNTIF(Questionário!A:A,'Checagem Referencial V29.09'!C14) -> 2
A15: 2. Planejamento | B15: Adesão e Rotina | C15: E2D1_2 | D15: A Secretaria Estadual de Educação elabora um calendário anual do CdG. | E15: 1 | F15: =IFERROR(IF(VLOOKUP(C15,Questionário!A:A,1,FALSE)=C15,"Ok","Ausente"),"Ausente") -> Ok | G15: =COUNTIF(Questionário!A:A,'Checagem Referencial V29.09'!C15) -> 1
A16: 2. Planejamento | B16: Adesão e Rotina | C16: E2D1_3 | D16: A Secretaria Estadual de Educação compartilha o calendário anual do CdG com a rede. | E16: 1;2;3;4 | F16: =IFERROR(IF(VLOOKUP(C16,Questionário!A:A,1,FALSE)=C16,"Ok","Ausente"),"Ausente") -> Ok | G16: =COUNTIF(Questionário!A:A,'Checagem Referencial V29.09'!C16) -> 1
A17: 2. Planejamento | B17: Adesão e Rotina | C17: E2D1_4 | D17: A Secretaria Estadual de Educação insere seu plano de ação no Sistema de Gestão para o Avanço Contínuo da Educação (Sigae) no prazo estipulado pelo cronograma pactuado com a rede. | E17: 1;2;3;4;5 | F17: =IFERROR(IF(VLOOKUP(C17,Questionário!A:A,1,FALSE)=C17,"Ok","Ausente"),"Ausente") -> Ok | G17: =COUNTIF(Questionário!A:A,'Checagem Referencial V29.09'!C17) -> 1
A18: 2. Planejamento | B18: Adesão e Rotina | C18: E2D1_5 | D18: As Regionais inserem seus planos de ação no Sistema de Gestão para o Avanço Contínuo da Educação (Sigae) no prazo estipulado pelo cronograma pactuado com a rede. | E18: 1;2;3;4;5 | F18: =IFERROR(IF(VLOOKUP(C18,Questionário!A:A,1,FALSE)=C18,"Ok","Ausente"),"Ausente") -> Ok | G18: =COUNTIF(Questionário!A:A,'Checagem Referencial V29.09'!C18) -> 1
A19: 2. Planejamento | B19: Adesão e Rotina | C19: E2D1_7 | D19: O plano de ação da Secretaria Estadual de Educação é orientado pelos objetivos estratégicos. | E19: 1;5 | F19: =IFERROR(IF(VLOOKUP(C19,Questionário!A:A,1,FALSE)=C19,"Ok","Ausente"),"Ausente") -> Ok | G19: =COUNTIF(Questionário!A:A,'Checagem Referencial V29.09'!C19) -> 1
A20: 2. Planejamento | B20: Adesão e Rotina | C20: E2D1_8 | D20: O plano de ação das Regionais é orientado pelos objetivos estratégicos estabelecidos pela Secretaria Estadual de Educação. | E20: 1;2;5 | F20: =IFERROR(IF(VLOOKUP(C20,Questionário!A:A,1,FALSE)=C20,"Ok","Ausente"),"Ausente") -> Ok | G20: =COUNTIF(Questionário!A:A,'Checagem Referencial V29.09'!C20) -> 2
A21: 2. Planejamento | B21: Adesão e Rotina | C21: E2D1_10 | D21: O plano de ação da Secretaria Estadual de Educação é elaborado com base no diagnóstico feito no ano anterior, com foco nos resultados de aprendizagem e fluxo (aprovação e abandono). | E21: 1 | F21: =IFERROR(IF(VLOOKUP(C21,Questionário!A:A,1,FALSE)=C21,"Ok","Ausente"),"Ausente") -> Ok | G21: =COUNTIF(Questionário!A:A,'Checagem Referencial V29.09'!C21) -> 1
A22: 2. Planejamento | B22: Adesão e Rotina | C22: E2D1_11 | D22: Os planos de ação das Regionais são elaborados com base no diagnóstico feito no ano anterior, com foco nos resultados de aprendizagem e fluxo (aprovação e abandono). | E22: 1;2;3 | F22: =IFERROR(IF(VLOOKUP(C22,Questionário!A:A,1,FALSE)=C22,"Ok","Ausente"),"Ausente") -> Ok | G22: =COUNTIF(Questionário!A:A,'Checagem Referencial V29.09'!C22) -> 1
A23: 2. Planejamento | B23: Engajamento | C23: E2D2_13 | D23: Há profissionais de diferentes áreas da Secretaria Estadual de Educação (área financeira, pedagógica, infraestrutura, pessoas, etc.) com atribuições de tarefas e ações no plano de ações da secretaria. | E23: 1 | F23: =IFERROR(IF(VLOOKUP(C23,Questionário!A:A,1,FALSE)=C23,"Ok","Ausente"),"Ausente") -> Ok | G23: =COUNTIF(Questionário!A:A,'Checagem Referencial V29.09'!C23) -> 2
... A44: 3. Execução | B44: Engajamento | C44: E3D2_14 | D44: A equipe gestora da Secretaria Estadual de Educação acompanha a execução do seu plano de ação. | E44: 1;2 | F44: =IFERROR(IF(VLOOKUP(C44,Questionário!A:A,1,FALSE)=C44,"Ok","Ausente"),"Ausente") -> Ok | G44: =COUNTIF(Questionário!A:A,'Checagem Referencial V29.09'!C44) -> 3
A45: 3. Execução | B45: Engajamento | C45: E3D2_15 | D45: A equipe gestora da Secretaria Estadual de Educação apoia os profissionais responsáveis pelas ações (do seu plano de ação) | E45: 1 | F45: =IFERROR(IF(VLOOKUP(C45,Questionário!A:A,1,FALSE)=C45,"Ok","Ausente"),"Ausente") -> Ausente | G45: =COUNTIF(Questionário!A:A,'Checagem Referencial V29.09'!C45) -> 0 | H45: Confirmada a exclusão por e-mail pela Mariana Bittar em 25.10.23
A46: 3. Execução | B46: Autonomia | C46: E3D3_23 | D46: Há ACGs suficientes para realizar adequadamente o acompanhamento das atividades nas escolas. | E46: 1;2;3;4 | F46: =IFERROR(IF(VLOOKUP(C46,Questionário!A:A,1,FALSE)=C46,"Ok","Ausente"),"Ausente") -> Ok | G46: =COUNTIF(Questionário!A:A,'Checagem Referencial V29.09'!C46) -> 1
A47: 3. Execução | B47: Autonomia | C47: E3D3_25 | D47: A Secretaria conta com uma equipe técnica para acompanhamento e execução das ações prevista no CdG. | E47: 1;2 | F47: =IFERROR(IF(VLOOKUP(C47,Questionário!A:A,1,FALSE)=C47,"Ok","Ausente"),"Ausente") -> Ok | G47: =COUNTIF(Questionário!A:A,'Checagem Referencial V29.09'!C47) -> 3
A48: 3. Execução | B48: Apoio entre Instâncias | C48: E3D4_26 | D48: A Secretaria Estadual de Educação acompanha e apoia o processo de execução do plano de ação das regionais. | E48: 1;2 | F48: =IFERROR(IF(VLOOKUP(C48,Questionário!A:A,1,FALSE)=C48,"Ok","Ausente"),"Ausente") -> Ok | G48: =COUNTIF(Questionário!A:A,'Checagem Referencial V29.09'!C48) -> 2
A49: 3. Execução | B49: Apoio entre Instâncias | C49: E3D4_29 | D49: A Secretaria orienta as regionais para a inserção dos dados sobre as tarefas e resultados dos seus respectivos planos de ação. | E49: 1;2;3;4 | F49: =IFERROR(IF(VLOOKUP(C49,Questionário!A:A,1,FALSE)=C49,"Ok","Ausente"),"Ausente") -> Ok | G49: =COUNTIF(Questionário!A:A,'Checagem Referencial V29.09'!C49) -> 1
A50: 3. Execução | B50: Customização | C50: E3D5_32 | D50: A Secretaria fez customizações em ao menos um processo da etapa de execução (indicadores específicos, formulários para registro de informações, roteiros de análise e de orientação e sistematização das atividades, instruções para o uso do sistema de informações) | E50: 1;2;3 | F50: =IFERROR(IF(VLOOKUP(C50,Questionário!A:A,1,FALSE)=C50,"Ok","Ausente"),"Ausente") -> Ok | G50: =COUNTIF(Questionário!A:A,'Checagem Referencial V29.09'!C50) -> 1
A51: 3. Execução | B51: Customização | C51: E3D5_36 | D51: Houve adaptações nos protocolos de execução, considerando o contexto e a realidade da rede. | E51: 1;2;3 | F51: =IFERROR(IF(VLOOKUP(C51,Questionário!A:A,1,FALSE)=C51,"Ok","Ausente"),"Ausente") -> Ok | G51: =COUNTIF(Questionário!A:A,'Checagem Referencial V29.09'!C51) -> 2
A52: 4. Avaliação de Resultados | B52: Adesão e Rotina | C52: E4D1_2 | D52: O grupo gestor da regional avalia se a regional e seu conjunto de escolas estão atingindo os resultados propostos, com base nos indicadores de execução (do plano de ação) e estruturantes e posta sua analise no SIGAE no prazo previsto no calendário. | E52: 1;2;3 | F52: =IFERROR(IF(VLOOKUP(C52,Questionário!A:A,1,FALSE)=C52,"Ok","Ausente"),"Ausente") -> Ok | G52: =COUNTIF(Questionário!A:A,'Checagem Referencial V29.09'!C52) -> 1
A53: 4. Avaliação de Resultados | B53: Adesão e Rotina | C53: E4D1_3 | D53: O grupo gestor da Secretaria avalia se a Secretaria, regionais e escolas estão atingindo os resultados propostos, com base nos indicadores de execução (do plano de ação) e estruturantes no prazo previsto no calendário. | E53: 1;5 | F53: =IFERROR(IF(VLOOKUP(C53,Questionário!A:A,1,FALSE)=C53,"Ok","Ausente"),"Ausente") -> Ok | G53: =COUNTIF(Questionário!A:A,'Checagem Referencial V29.09'!C53) -> 1
A54: 4. Avaliação de Resultados | B54: Engajamento | C54: E4D2_7 | D54: Os profissionais com atribuições de ações no plano da Secretaria Estadual de Educação participam da N4. | E54: 1;5 | F54: =IFERROR(IF(VLOOKUP(C54,Questionário!A:A,1,FALSE)=C54,"Ok","Ausente"),"Ausente") -> Ok | G54: =COUNTIF(Questionário!A:A,'Checagem Referencial V29.09'!C54) -> 1
A55: 4. Avaliação de Resultados | B55: Autonomia | C55: E4D3_4 | D55: A equipe técnica da Secretaria Estadual de Educação realiza a extração dos dados do sistema da Secretaria e os inserem no Sistema de Gestão para o Avanço Contínuo da Educação (Sigae). | E55: 1;2 | F55: =IFERROR(IF(VLOOKUP(C55,Questionário!A:A,1,FALSE)=C55,"Ok","Ausente"),"Ausente") -> Ok | G55: =COUNTIF(Questionário!A:A,'Checagem Referencial V29.09'!C55) -> 1
A56: 4. Avaliação de Resultados | B56: Autonomia | C56: E4D3_10 | D56: A Secretaria Estadual de Educação dispõe de recursos técnicos (sistemas, base de dados estruturada, computadores, softwares adequados, etc.) necessários para calcular os indicadores educacionais com qualidade e autonomia. | E56: 1 | F56: =IFERROR(IF(VLOOKUP(C56,Questionário!A:A,1,FALSE)=C56,"Ok","Ausente"),"Ausente") -> Ok | G56: =COUNTIF(Questionário!A:A,'Checagem Referencial V29.09'!C56) -> 1
A57: 4. Avaliação de Resultados | B57: Autonomia | C57: E4D3_11 | D57: A Secretaria Estadual de Educação possui uma equipe de profissionais que conhece as formas de cálculo e metodologias utilizadas para calcular os indicadores, produzir e homologar informações e relatórios para a SMAR. | E57: 1 | F57: =IFERROR(IF(VLOOKUP(C57,Questionário!A:A,1,FALSE)=C57,"Ok","Ausente"),"Ausente") -> Ok | G57: =COUNTIF(Questionário!A:A,'Checagem Referencial V29.09'!C57) -> 1
... A60: 4. Avaliação de Resultados | B60: Apoio entre Instancias | C60: E4D4_21 | D60: Os profissionais da Secretaria Estadual de Educação analisam os indicadores de execução do plano de ação e os indicadores estruturantes das Regionais. | E60: 1;2 | F60: =IFERROR(IF(VLOOKUP(C60,Questionário!A:A,1,FALSE)=C60,"Ok","Ausente"),"Ausente") -> Ok | G60: =COUNTIF(Questionário!A:A,'Checagem Referencial V29.09'!C60) -> 1
A61: 4. Avaliação de Resultados | B61: Apoio entre Instancias | C61: E4D4_22 | D61: Os profissionais da Secretaria Estadual de Educação dialogam com a equipe gestora da regional sobre os resultados dos indicadores de execução do plano de ação e estruturantes das Regionais. | E61: 1;2 | F61: =IFERROR(IF(VLOOKUP(C61,Questionário!A:A,1,FALSE)=C61,"Ok","Ausente"),"Ausente") -> Ausente | G61: =COUNTIF(Questionário!A:A,'Checagem Referencial V29.09'!C61) -> 0 | H61: Excluído após revisão de Mariana Bittar em 13.10
A62: 4. Avaliação de Resultados | B62: Customização | C62: E4D5_23 | D62: A Secretaria Estadual de Educação fez customizações em ao menos um processo da etapa de avaliação (adaptações nos processos, indicadores específicos, formulários para registro de informações, roteiros de análise e de orientação e sistematização das atividades, instruções para o uso do sistema de informações). | E62: 1 | F62: =IFERROR(IF(VLOOKUP(C62,Questionário!A:A,1,FALSE)=C62,"Ok","Ausente"),"Ausente") -> Ok | G62: =COUNTIF(Questionário!A:A,'Checagem Referencial V29.09'!C62) -> 1
...

Sheet Checagem_V1V2
A1: COD_FINAL_QUEST | B1: check_referencial
A2: E4D1_2 | B2: =VLOOKUP(A2,'Checagem Referencial V29.09'!C:C,1,FALSE) -> E4D1_2
A3: A1D1_1 | B3: =VLOOKUP(A3,'Checagem Referencial V29.09'!C:C,1,FALSE) -> A1D1_1
A4: A1D1_2 | B4: =VLOOKUP(A4,'Checagem Referencial V29.09'!C:C,1,FALSE) -> A1D1_2
A5: A1D1_3 | B5: =VLOOKUP(A5,'Checagem Referencial V29.09'!C:C,1,FALSE) -> A1D1_3
A6: A1D1_4 | B6: =VLOOKUP(A6,'Checagem Referencial V29.09'!C:C,1,FALSE) -> A1D1_4
A7: A1D1_5 | B7: =VLOOKUP(A7,'Checagem Referencial V29.09'!C:C,1,FALSE) -> A1D1_5
A8: A1D2_6 | B8: =VLOOKUP(A8,'Checagem Referencial V29.09'!C:C,1,FALSE) -> A1D2_6
A9: A1D2_7 | B9: =VLOOKUP(A9,'Checagem Referencial V29.09'!C:C,1,FALSE) -> A1D2_7
A10: A1D2_8 | B10: =VLOOKUP(A10,'Checagem Referencial V29.09'!C:C,1,FALSE) -> A1D2_8
A11: A1D2_9 | B11: =VLOOKUP(A11,'Checagem Referencial V29.09'!C:C,1,FALSE) -> A1D2_9
A12: A1D3_10 | B12: =VLOOKUP(A12,'Checagem Referencial V29.09'!C:C,1,FALSE) -> A1D3_10
A13: A1D3_12 | B13: =VLOOKUP(A13,'Checagem Referencial V29.09'!C:C,1,FALSE) -> A1D3_12
... A124: E6D5_27 | B124: =VLOOKUP(A124,'Checagem Referencial V29.09'!C:C,1,FALSE) -> E6D5_27

Sheet checagem_ref
A1: ref_29.09 | B1: ref 29.09 com a aba checagem referencial | C1: checagem referencial com o questionário
A2: E1D1_1 | B2: =IFERROR(IF(VLOOKUP(A2,'Checagem Referencial V29.09'!C:C,1,FALSE)=checagem_ref!A2,"Ok","Ausente"),"Ausente") -> Ok | C2: =IFERROR(IF(VLOOKUP(A2,Questionário!A:A,1,FALSE)=A2,"Ok","Ausente"),"Ausente") -> Ok
A3: E1D1_2 | B3: =IFERROR(IF(VLOOKUP(A3,'Checagem Referencial V29.09'!C:C,1,FALSE)=checagem_ref!A3,"Ok","Ausente"),"Ausente") -> Ok | C3: =IFERROR(IF(VLOOKUP(A3,Questionário!A:A,1,FALSE)=A3,"Ok","Ausente"),"Ausente") -> Ok
A4: E1D1_3 | B4: =IFERROR(IF(VLOOKUP(A4,'Checagem Referencial V29.09'!C:C,1,FALSE)=checagem_ref!A4,"Ok","Ausente"),"Ausente") -> Ok | C4: =IFERROR(IF(VLOOKUP(A4,Questionário!A:A,1,FALSE)=A4,"Ok","Ausente"),"Ausente") -> Ok
A5: E1D1_4 | B5: =IFERROR(IF(VLOOKUP(A5,'Checagem Referencial V29.09'!C:C,1,FALSE)=checagem_ref!A5,"Ok","Ausente"),"Ausente") -> Ok | C5: =IFERROR(IF(VLOOKUP(A5,Questionário!A:A,1,FALSE)=A5,"Ok","Ausente"),"Ausente") -> Ok
A6: E1D1_5 | B6: =IFERROR(IF(VLOOKUP(A6,'Checagem Referencial V29.09'!C:C,1,FALSE)=checagem_ref!A6,"Ok","Ausente"),"Ausente") -> Ok | C6: =IFERROR(IF(VLOOKUP(A6,Questionário!A:A,1,FALSE)=A6,"Ok","Ausente"),"Ausente") -> Ok
A7: E1D2_9 | B7: =IFERROR(IF(VLOOKUP(A7,'Checagem Referencial V29.09'!C:C,1,FALSE)=checagem_ref!A7,"Ok","Ausente"),"Ausente") -> Ok | C7: =IFERROR(IF(VLOOKUP(A7,Questionário!A:A,1,FALSE)=A7,"Ok","Ausente"),"Ausente") -> Ok
A8: E1D3_11 | B8: =IFERROR(IF(VLOOKUP(A8,'Checagem Referencial V29.09'!C:C,1,FALSE)=checagem_ref!A8,"Ok","Ausente"),"Ausente") -> Ok | C8: =IFERROR(IF(VLOOKUP(A8,Questionário!A:A,1,FALSE)=A8,"Ok","Ausente"),"Ausente") -> Ok
A9: E1D3_12 | B9: =IFERROR(IF(VLOOKUP(A9,'Checagem Referencial V29.09'!C:C,1,FALSE)=checagem_ref!A9,"Ok","Ausente"),"Ausente") -> Ok | C9: =IFERROR(IF(VLOOKUP(A9,Questionário!A:A,1,FALSE)=A9,"Ok","Ausente"),"Ausente") -> Ok
A10: E1D3_13 | B10: =IFERROR(IF(VLOOKUP(A10,'Checagem Referencial V29.09'!C:C,1,FALSE)=checagem_ref!A10,"Ok","Ausente"),"Ausente") -> Ok | C10: =IFERROR(IF(VLOOKUP(A10,Questionário!A:A,1,FALSE)=A10,"Ok","Ausente"),"Ausente") -> Ok
A11: E1D5_16 | B11: =IFERROR(IF(VLOOKUP(A11,'Checagem Referencial V29.09'!C:C,1,FALSE)=checagem_ref!A11,"Ok","Ausente"),"Ausente") -> Ok | C11: =IFERROR(IF(VLOOKUP(A11,Questionário!A:A,1,FALSE)=A11,"Ok","Ausente"),"Ausente") -> Ok
A12: E1D5_17 | B12: =IFERROR(IF(VLOOKUP(A12,'Checagem Referencial V29.09'!C:C,1,FALSE)=checagem_ref!A12,"Ok","Ausente"),"Ausente") -> Ok | C12: =IFERROR(IF(VLOOKUP(A12,Questionário!A:A,1,FALSE)=A12,"Ok","Ausente"),"Ausente") -> Ok
A13: E2D1_1 | B13: =IFERROR(IF(VLOOKUP(A13,'Checagem Referencial V29.09'!C:C,1,FALSE)=checagem_ref!A13,"Ok","Ausente"),"Ausente") -> Ok | C13: =IFERROR(IF(VLOOKUP(A13,Questionário!A:A,1,FALSE)=A13,"Ok","Ausente"),"Ausente") -> Ok
... A141: A4D5_23 | B141: =IFERROR(IF(VLOOKUP(A141,'Checagem Referencial V29.09'!C:C,1,FALSE)=checagem_ref!A141,"Ok","Ausente"),"Ausente") -> Ok | C141: =IFERROR(IF(VLOOKUP(A141,Questionário!A:A,1,FALSE)=A141,"Ok","Ausente"),"Ausente") -> Ok

Sheet Planilha2
B1: arrumado_quest | C1: questionário com a checagem referencial
A2: E4D1_2 | B2: E4D1_2 | C2: =IFERROR(IF(VLOOKUP(B2,'Checagem Referencial V29.09'!C:C,1,FALSE)=B2,"Ok","Ausente"),"Ausente") -> Ok
A3: A1D1_1 | B3: A1D1_1 | C3: =IFERROR(IF(VLOOKUP(B3,'Checagem Referencial V29.09'!C:C,1,FALSE)=B3,"Ok","Ausente"),"Ausente") -> Ok
A4: A1D1_2 | B4: A1D1_2 | C4: =IFERROR(IF(VLOOKUP(B4,'Checagem Referencial V29.09'!C:C,1,FALSE)=B4,"Ok","Ausente"),"Ausente") -> Ok
A5: A1D1_3 | B5: A1D1_3 | C5: =IFERROR(IF(VLOOKUP(B5,'Checagem Referencial V29.09'!C:C,1,FALSE)=B5,"Ok","Ausente"),"Ausente") -> Ok
A6: A1D1_4 | B6: A1D1_4 | C6: =IFERROR(IF(VLOOKUP(B6,'Checagem Referencial V29.09'!C:C,1,FALSE)=B6,"Ok","Ausente"),"Ausente") -> Ok
A7: A1D1_5 | B7: A1D1_5 | C7: =IFERROR(IF(VLOOKUP(B7,'Checagem Referencial V29.09'!C:C,1,FALSE)=B7,"Ok","Ausente"),"Ausente") -> Ok
A8: A1D2_6 | B8: A1D2_6 | C8: =IFERROR(IF(VLOOKUP(B8,'Checagem Referencial V29.09'!C:C,1,FALSE)=B8,"Ok","Ausente"),"Ausente") -> Ok
A9: A1D2_7 | B9: A1D2_7 | C9: =IFERROR(IF(VLOOKUP(B9,'Checagem Referencial V29.09'!C:C,1,FALSE)=B9,"Ok","Ausente"),"Ausente") -> Ok
A10: A1D2_8 | B10: A1D2_8 | C10: =IFERROR(IF(VLOOKUP(B10,'Checagem Referencial V29.09'!C:C,1,FALSE)=B10,"Ok","Ausente"),"Ausente") -> Ok
A11: A1D2_9 | B11: A1D2_9 | C11: =IFERROR(IF(VLOOKUP(B11,'Checagem Referencial V29.09'!C:C,1,FALSE)=B11,"Ok","Ausente"),"Ausente") -> Ok
A12: A1D3_10 | B12: A1D3_10 | C12: =IFERROR(IF(VLOOKUP(B12,'Checagem Referencial V29.09'!C:C,1,FALSE)=B12,"Ok","Ausente"),"Ausente") -> Ok
A13: A1D3_12 | B13: A1D3_12 | C13: =IFERROR(IF(VLOOKUP(B13,'Checagem Referencial V29.09'!C:C,1,FALSE)=B13,"Ok","Ausente"),"Ausente") -> Ok
... A132: Não se aplica | B132: E5_DXA | C132: =IFERROR(IF(VLOOKUP(B132,'Checagem Referencial V29.09'!C:C,1,FALSE)=B132,"Ok","Ausente"),"Ausente") -> Ausente
